Workbook

Sheet Balance Sheet 
A2: Balance Sheet of Hindustan Unilever (in Rs. Cr.) | B2: 46106 | C2: 46105 | D2: 46104 | E2: 46103 | F2: 46102 | I2: P-2030 | J2: P-2029 | K2: P-2028 | L2: P-2027 | M2: P-2026
B3: 12 mths | C3: 12 mths | D3: 12 mths | E3: 12 mths | F3: 12 mths
A4: EQUITIES AND LIABILITIES
A5: SHAREHOLDER'S FUNDS
A6: Equity Share Capital | B6: 235 | C6: 235 | D6: 235 | E6: 235 | F6: 235 | I6: =B6 -> 235 | J6: =C6 -> 235 | K6: =D6 -> 235 | L6: =E6 -> 235 | M6: =F6 -> 235
A7: Total Share Capital | B7: 235 | C7: 235 | D7: 235 | E7: 235 | F7: 235
A8: Reserves and Surplus | B8: 48918 | C8: 50738 | D8: 49986 | E8: 48525 | F8: 47199 | I8: =J8+'P&L'!I29 -> 99484.869 | J8: =K8+'P&L'!J29 -> 88223.492 | K8: =L8+'P&L'!K29 -> 77199.698 | L8: =M8+'P&L'!L29 -> 66495.956 | M8: =B9+'P&L'!M29 -> 57260.488
A9: Total Reserves and Surplus | B9: 48918 | C9: 50738 | D9: 49986 | E9: 48525 | F9: 47199
A10: Total Shareholders Funds | B10: 49153 | C10: 50973 | D10: 50221 | E10: 48760 | F10: 47434 | I10: =I6+I8 -> 99719.869 | J10: =J6+J8 -> 88458.492 | K10: =K6+K8 -> 77434.698 | L10: =L6+L8 -> 66730.956 | M10: =M6+M8 -> 57495.488
A11: NON-CURRENT LIABILITIES
A12: Long Term Borrowings | B12: 0 | C12: 0 | D12: 0 | E12: 0 | F12: 0 | I12: 0 | J12: 0 | K12: 0 | L12: 0 | M12: 0
A13: Deferred Tax Liabilities [Net] | B13: 6583 | C13: 6454 | D13: 6325 | E13: 6141 | F13: 5986 | I13: =$B$13 -> 6583 | J13: =$B$13 -> 6583 | K13: =$B$13 -> 6583 | L13: =$B$13 -> 6583 | M13: =B13 -> 6583
A14: Other Long Term Liabilities | B14: 5396 | C14: 5695 | D14: 2317 | E14: 2339 | F14: 2304 | I14: =$B$14 -> 5396 | J14: =$B$14 -> 5396 | K14: =$B$14 -> 5396 | L14: =$B$14 -> 5396 | M14: =$B$14 -> 5396
A15: Long Term Provisions | B15: 1509 | C15: 1551 | D15: 1335 | E15: 1553 | F15: 1551 | I15: =$B$15 -> 1509 | J15: =$B$15 -> 1509 | K15: =$B$15 -> 1509 | L15: =$B$15 -> 1509 | M15: =$B$15 -> 1509
A16: Total Non-Current Liabilities | B16: 13488 | C16: 13700 | D16: 9977 | E16: 10033 | F16: 9841 | I16: =$B$16 -> 13488 | J16: =$B$16 -> 13488 | K16: =$B$16 -> 13488 | L16: =$B$16 -> 13488 | M16: =$B$16 -> 13488
A17: CURRENT LIABILITIES
A18: Short Term Borrowings | B18: 0 | C18: 0 | D18: 0 | E18: 0 | F18: 0
A19: Trade Payables | B19: 10998 | C19: 10148 | D19: 9391 | E19: 8864 | F19: 8627 | I19: =B75*B77% -> 11511.054 | J19: =C75*C77% -> 11268.205 | K19: =D75*D77% -> 10941.056 | L19: =E75*E77% -> 9440.2291 | M19: =F75*F77% -> 8527.451
A20: Other Current Liabilities | B20: 4013 | C20: 1926 | D20: 1857 | E20: 1746 | F20: 1723 | I20: =B74*B79% -> 4200.2054 | J20: =C74*C79% -> 4111.5935 | K20: =D74*D79% -> 3992.222 | L20: =E74*E79% -> 3444.5935 | M20: =F74*F79% -> 3111.5349
A21: Short Term Provisions | B21: 661 | C21: 329 | D21: 379 | E21: 334 | F21: 491 | I21: 661 | J21: 661 | K21: 661 | L21: 661 | M21: 661
A22: Total Current Liabilities | B22: 15672 | C22: 12403 | D22: 11627 | E22: 10944 | F22: 10841 | I22: =SUM(I19:I21) -> 16372.259 | J22: =SUM(J19:J21) -> 16040.798 | K22: =SUM(K19:K21) -> 15594.278 | L22: =SUM(L19:L21) -> 13545.823 | M22: =SUM(M19:M21) -> 12299.986
A23: Total Capital And Liabilities | B23: 78313 | C23: 77076 | D23: 71825 | E23: 69737 | F23: 68116 | I23: =I10+I16+I22 -> 129580.13 | J23: =J10+J16+J22 -> 117987.29 | K23: =K10+K16+K22 -> 106516.98 | L23: =L10+L16+L22 -> 93764.779 | M23: =M10+M16+M22 -> 83283.474
A24: ASSETS
A25: NON-CURRENT ASSETS
A26: Tangible Assets | B26: 7710 | C26: 7178 | D26: 6189 | E26: 5813 | F26: 5786 | I26: =J26*84% -> 3224.4141 | J26: =K26*84% -> 3838.5882 | K26: =L26*84% -> 4569.7478 | L26: =M26*84% -> 5440.176 | M26: =B26*84% -> 6476.4
A27: Intangible Assets | B27: 45197 | C27: 45201 | D27: 45216 | E27: 45221 | F27: 45241 | I27: =J27*84% -> 18901.925 | J27: =K27*84% -> 22502.292 | K27: =L27*84% -> 26788.443 | L27: =M27*84% -> 31891.003 | M27: =B27*84% -> 37965.48
A28: Capital Work-In-Progress | B28: 956 | C28: 915 | D28: 1020 | E28: 901 | F28: 623 | I28: =$B$28 -> 956 | J28: =$B$28 -> 956 | K28: =$B$28 -> 956 | L28: =$B$28 -> 956 | M28: =$B$28 -> 956
A29: Other Assets | B29: 0 | C29: 0 | D29: 0 | E29: 0 | F29: 0 | I29: =$B$29 -> 0 | J29: =$B$29 -> 0 | K29: =$B$29 -> 0 | L29: =$B$29 -> 0 | M29: =$B$29 -> 0
A30: Fixed Assets | B30: 53863 | C30: 53294 | D30: 52425 | E30: 51935 | F30: 51650 | I30: =$B$30 -> 53863 | J30: =$B$30 -> 53863 | K30: =$B$30 -> 53863 | L30: =$B$30 -> 53863 | M30: =$B$30 -> 53863
A31: Non-Current Investments | B31: 988 | C31: 983 | D31: 983 | E31: 612 | F31: 312
A32: Deferred Tax Assets [Net] | B32: 0 | C32: 0 | D32: 0 | E32: 0 | F32: 0
A33: Long Term Loans And Advances | B33: 332 | C33: 392 | D33: 339 | E33: 541 | F33: 520
A34: Other Non-Current Assets | B34: 2231 | C34: 2111 | D34: 2029 | E34: 2002 | F34: 1994
A35: Total Non-Current Assets | B35: 57414 | C35: 56780 | D35: 55776 | E35: 55090 | F35: 54476 | I35: =$B$35 -> 57414 | J35: =$B$35 -> 57414 | K35: =$B$35 -> 57414 | L35: =$B$35 -> 57414 | M35: =$B$35 -> 57414
A36: CURRENT ASSETS
A37: Current Investments | B37: 3614 | C37: 4510 | D37: 2811 | E37: 3510 | F37: 2683 | I37: =$B$37 -> 3614 | J37: =$B$37 -> 3614 | K37: =$B$37 -> 3614 | L37: =$B$37 -> 3614 | M37: =$B$37 -> 3614
A38: Inventories | B38: 4161 | C38: 3812 | D38: 4031 | E38: 3890 | F38: 3383 | I38: =B75*B78% -> 4355.1096 | J38: =C75*C78% -> 4263.2296 | K38: =D75*D78% -> 4139.4557 | L38: =E75*E78% -> 3571.6306 | M38: =F75*F78% -> 3226.2887
A39: Trade Receivables | B39: 3450 | C39: 2690 | D39: 2735 | E39: 1932 | F39: 1648 | I39: =B74*B76% -> 3610.9416 | J39: =C74*C76% -> 3534.7614 | K39: =D74*D76% -> 3432.1371 | L39: =E74*E76% -> 2961.3376 | M39: =F74*F76% -> 2675.0051
A40: Cash And Cash Equivalents | B40: 7293 | C40: 7216 | D40: 4422 | E40: 3618 | F40: 4321 | I40: 7293 | J40: 7293 | K40: 7293 | L40: 7293 | M40: 7293
A41: Short Term Loans And Advances | B41: 45 | C41: 37 | D41: 35 | E41: 34 | F41: 0 | I41: =$B$41 -> 45 | J41: =$B$41 -> 45 | K41: =$B$41 -> 45 | L41: =$B$41 -> 45 | M41: =$B$41 -> 45
...

Sheet P&L
A1: Profit & Loss account of Hindustan Unilever (in Rs. Cr.) | B1: 46106 | C1: 46105 | D1: 46104 | E1: 46103 | F1: 46102 | I1: P-2030 | J1: P-2029 | K1: P-2028 | L1: P-2027 | M1: P-2026
B2: 12 mths | C2: 12 mths | D2: 12 mths | E2: 12 mths | F2: 12 mths
A3: INCOME
A4: Revenue From Operations [Gross] | B4: 60680 | C4: 59579 | D4: 58154 | E4: 50336 | F4: 45311
A5: Less: Excise/Sevice Tax/Other Levies | B5: 0 | C5: 0 | D5: 0 | E5: 0 | F5: 0
A6: Revenue From Operations [Net] | B6: 60680 | C6: 59579 | D6: 58154 | E6: 50336 | F6: 45311 | I6: =B6*(1+0.06) -> 64320.8 | J6: =C6*(1+0.06) -> 63153.74 | K6: =D6*(1+0.06) -> 61643.24 | L6: =E6*(1+0.06) -> 53356.16 | M6: =F6*(1+0.06) -> 48029.66
A7: Total Operating Revenues | B7: 61469 | C7: 60469 | D7: 59144 | E7: 51193 | F7: 45996 | I7: =I6 -> 64320.8 | J7: =J6 -> 63153.74 | K7: =K6 -> 61643.24 | L7: =L6 -> 53356.16 | M7: =M6 -> 48029.66
A8: Other Income | B8: 1177 | C8: 973 | D8: 640 | E8: 393 | F8: 513 | I8: =B8*106% -> 1247.62 | J8: =C8*106% -> 1031.38 | K8: =D8*106% -> 678.4 | L8: =E8*106% -> 416.58 | M8: =F8*106% -> 543.78
A9: Total Revenue | B9: 62646 | C9: 61442 | D9: 59784 | E9: 51586 | F9: 46509 | I9: =I7+I8 -> 65568.42 | J9: =J7+J8 -> 64185.12 | K9: =K7+K8 -> 62321.64 | L9: =L7+L8 -> 53772.74 | M9: =M7+M8 -> 48573.44
A10: EXPENSES
A11: Cost Of Materials Consumed | B11: 17698 | C11: 17791 | D11: 19229 | E11: 15869 | F11: 14951 | I11: =I9*$D$63% -> 18523.607 | J11: =J9*$D$63% -> 18132.814 | K11: =K9*$D$63% -> 17606.366 | L11: =L9*$D$63% -> 15191.233 | M11: =M9*$D$63% -> 13722.388
A12: Purchase Of Stock-In Trade | B12: 12584 | C12: 11544 | D12: 11968 | E12: 9274 | F12: 7117 | I12: =I9*$D$64% -> 13171.04 | J12: =J9*$D$64% -> 12893.17 | K12: =K9*$D$64% -> 12518.844 | L12: =L9*$D$64% -> 10801.586 | M12: =M9*$D$64% -> 9757.1779
A13: Operating And Direct Expenses | B13: 0 | C13: 0 | D13: 0 | E13: 0 | F13: 0
A14: Changes In Inventories Of FG,WIP And Stock-In Trade | B14: -106 | C14: -8 | D14: -53 | E14: -19 | F14: -391 | I14: =-I9*$D$65% -> -110.94487 | J14: =-J9*$D$65% -> -108.60426 | K14: =-K9*$D$65% -> -105.45117 | L14: =-L9*$D$65% -> -90.986024 | M14: =-M9*$D$65% -> -82.188562
A15: Employee Benefit Expenses | B15: 2840 | C15: 2782 | D15: 2665 | E15: 2399 | F15: 2229
A16: Finance Costs | B16: 364 | C16: 302 | D16: 101 | E16: 98 | F16: 108 | I16: =I9*$C$55 -> 393.41052 | J16: =J9*$C$55 -> 385.11072 | K16: =K9*$C$55 -> 373.92984 | L16: =L9*$C$55 -> 322.63644 | M16: =M9*$C$55 -> 291.44064
A17: Depreciation And Amortisation Expenses | B17: 1224 | C17: 1097 | D17: 1030 | E17: 1025 | F17: 1012
A18: Other Expenses | B18: 14164 | C18: 14170 | D18: 11703 | E18: 11167 | F18: 10766
A19: Total Expenses | B19: 48768 | C19: 47678 | D19: 46643 | E19: 39813 | F19: 35792 | I19: =I9-I9*$C$54 -> 50159.841 | J19: =J9-J9*$C$54 -> 49101.617 | K19: =K9-K9*$C$54 -> 47676.055 | L19: =L9-L9*$C$54 -> 41136.146 | M19: =M9-M9*$C$54 -> 37158.682
A20: Profit/Loss Before Exceptional, ExtraOrdinary Items And Tax | B20: 13878 | C20: 13764 | D20: 13141 | E20: 11773 | F20: 10717
A21: Exceptional Items | B21: 422 | C21: -89 | D21: -62 | E21: -34 | F21: -227
A22: Profit/Loss Before Tax | B22: 14300 | C22: 13675 | D22: 13079 | E22: 11739 | F22: 10490 | I22: =D62-I16 -> 15015.168 | J22: =E62-J16 -> 14698.392 | K22: =F62-K16 -> 14271.656 | L22: =G62-L16 -> 12313.957 | M22: =H62-M16 -> 11123.318
A23: Tax Expenses-Continued Operations
A24: Tax Expenses-Continued Operations | B24: 3525 | C24: 3446 | D24: 2922 | E24: 2778 | F24: 2458 | I24: =I22*$C$56 -> 3753.792 | J24: =J22*$C$56 -> 3674.5981 | K24: =K22*$C$56 -> 3567.9139 | L24: =L22*$C$56 -> 3078.4894 | M24: =M22*$C$56 -> 2780.8294 | P24: =P22*F56 -> 0
A25: Less: MAT Credit Entitlement | B25: 0 | C25: 0 | D25: 0 | E25: 0 | F25: 0
A26: Deferred Tax | B26: 131 | C26: 115 | D26: 195 | E26: 143 | F26: 78
A27: Tax For Earlier Years | B27: 0 | C27: 0 | D27: 0 | E27: 0 | F27: 0
A28: Total Tax Expenses | B28: 3656 | C28: 3561 | D28: 3117 | E28: 2921 | F28: 2536
A29: Profit/Loss After Tax And Before ExtraOrdinary Items | B29: 10644 | C29: 10114 | D29: 9962 | E29: 8818 | F29: 7954 | I29: =I22-I24 -> 11261.376 | J29: =J22-J24 -> 11023.794 | K29: =K22-K24 -> 10703.742 | L29: =L22-L24 -> 9235.4681 | M29: =M22-M24 -> 8342.4883
A30: Profit/Loss From Continuing Operations | B30: 10644 | C30: 10114 | D30: 9962 | E30: 8818 | F30: 7954
A31: Profit/Loss For The Period | B31: 10644 | C31: 10114 | D31: 9962 | E31: 8818 | F31: 7954
A32: OTHER ADDITIONAL INFORMATION
A33: EARNINGS PER SHARE
A34: Basic EPS (Rs.) | B34: 45.3 | C34: 43.05 | D34: 42.4 | E34: 37.53 | F34: 33.85
A35: Diluted EPS (Rs.) | B35: 45.3 | C35: 43.05 | D35: 42.4 | E35: 37.53 | F35: 33.85
A36: VALUE OF IMPORTED AND INDIGENIOUS RAW MATERIALS STORES, SPARES AND LOOSE TOOLS
A37: Imported Raw Materials | B37: 0 | C37: 0 | D37: 0 | E37: 0 | F37: 0
A38: Indigenous Raw Materials | B38: 0 | C38: 0 | D38: 0 | E38: 0 | F38: 0
A39: STORES, SPARES AND LOOSE TOOLS
A40: Imported Stores And Spares | B40: 0 | C40: 0 | D40: 0 | E40: 0 | F40: 0
...

Sheet Cash Flow 
A1: Cash Flow of Hindustan Unilever (in Rs. Cr.) | B1: 46106 | C1: 46105 | D1: 46104 | E1: 46103 | F1: 46102 | I1: P-2030 | J1: P-2029 | K1: P-2028 | L1: P-2027 | M1: P-2026
B2: 12 mths | C2: 12 mths | D2: 12 mths | E2: 12 mths | F2: 12 mths
A3: Net Profit/Loss Before Extraordinary Items And Tax | B3: 14300 | C3: 13675 | D3: 13079 | E3: 11739 | F3: 10490 | I3: ='P&L'!I22 -> 15015.168 | J3: ='P&L'!J22 -> 14698.392 | K3: ='P&L'!K22 -> 14271.656 | L3: ='P&L'!L22 -> 12313.957 | M3: ='P&L'!M22 -> 11123.318
A4: Net CashFlow From Operating Activities | B4: 11606 | C4: 14884 | D4: 9626 | E4: 8964 | F4: 8957 | I4: ='P&L'!I29+'P&L'!$B$17 -> 12485.376 | J4: ='P&L'!J29+'P&L'!$B$17 -> 12247.794 | K4: ='P&L'!K29+'P&L'!$B$17 -> 11927.742 | L4: ='P&L'!L29+'P&L'!$B$17 -> 10459.468 | M4: ='P&L'!M29+'P&L'!$B$17 -> 9566.4883
A5: Net Cash Used In Investing Activities | B5: 6763 | C5: -4971 | D5: -1062 | E5: -1732 | F5: -1367 | I5: =-'P&L'!C66 -> -1311.3684 | J5: =-'P&L'!D66 -> -1283.7024 | K5: =-'P&L'!E66 -> -1246.4328 | L5: =-'P&L'!F66 -> -1075.4548 | M5: =-'P&L'!G66 -> -971.4688
A6: Net Cash Used From Financing Activities | B6: -13031 | C6: -9890 | D6: -8966 | E6: -7984 | F6: -9280 | I6: =0 -> 0 | J6: =0 -> 0 | K6: =0 -> 0 | L6: =0 -> 0 | M6: =0 -> 0
A7: Foreign Exchange Gains / Losses | B7: 0 | C7: 0 | D7: 0 | E7: 0 | F7: 0 | I7: =0 -> 0 | J7: =0 -> 0 | K7: =0 -> 0 | L7: =0 -> 0 | M7: =0 -> 0
A8: Adjustments On Amalgamation Merger Demerger Others | B8: 0 | C8: 0 | D8: 0 | E8: 0 | F8: 0 | I8: =0 -> 0 | J8: =0 -> 0 | K8: =0 -> 0 | L8: =0 -> 0 | M8: =0 -> 0
A9: Net Inc/Dec In Cash And Cash Equivalents | B9: 5338 | C9: 23 | D9: -402 | E9: -752 | F9: -1690 | I9: =SUM(I3:I8) -> 26189.176 | J9: =SUM(J3:J8) -> 25662.484 | K9: =SUM(K3:K8) -> 24952.964 | L9: =SUM(L3:L8) -> 21697.971 | M9: =SUM(M3:M8) -> 19718.337
A10: Cash And Cash Equivalents Begin of Year | B10: 609 | C10: 586 | D10: 988 | E10: 1740 | F10: 3430 | I10: =0 -> 0 | J10: =0 -> 0 | K10: =0 -> 0 | L10: =0 -> 0 | M10: =0 -> 0
A11: Cash And Cash Equivalents End Of Year | B11: 5947 | C11: 609 | D11: 586 | E11: 988 | F11: 1740 | I11: =$B$11 -> 5947 | J11: =$B$11 -> 5947 | K11: =$B$11 -> 5947 | L11: =$B$11 -> 5947 | M11: =$B$11 -> 5947
